<robot
  name="soybot_1">
  <link
    name="base_link">
    <inertial>
      <origin
        xyz="-1.15 0.55274 -0.039417"
        rpy="0 0 0" />
      <mass
        value="357.06" />
      <inertia
        ixx="197.79"
        ixy="-3.3723E-14"
        ixz="0.00044033"
        iyy="340.98"
        iyz="-8.6326"
        izz="489.98" />
    </inertial>
    <visual>
      <origin
        xyz="0 0 0"
        rpy="0 0 0" />
      <geometry>
        <mesh
          filename="package://soybot_1/meshes/base_link.STL" />
      </geometry>
      <material
        name="">
        <color
          rgba="0.75294 0.75294 0.75294 1" />
      </material>
    </visual>
    <collision>
      <origin
        xyz="0 0 0"
        rpy="0 0 0" />
      <geometry>
        <mesh
          filename="package://soybot_1/meshes/base_link.STL" />
      </geometry>
    </collision>
  </link>
  <link
    name="Right_wheel">
    <inertial>
      <origin
        xyz="2.8511E-13 0.077003 1.6755E-05"
        rpy="0 0 0" />
      <mass
        value="17.568" />
      <inertia
        ixx="0.0011571"
        ixy="-3.6541E-13"
        ixz="8.5652E-17"
        iyy="8.1597E-08"
        iyz="-8.1174E-06"
        izz="0.0011571" />
    </inertial>
    <visual>
      <origin
        xyz="0 0 0"
        rpy="0 0 0" />
      <geometry>
        <mesh
          filename="package://soybot_1/meshes/Right_wheel.STL" />
      </geometry>
      <material
        name="">
        <color
          rgba="0.65098 0.61961 0.58824 1" />
      </material>
    </visual>
    <collision>
      <origin
        xyz="0 0 0"
        rpy="0 0 0" />
      <geometry>
        <mesh
          filename="package://soybot_1/meshes/Right_wheel.STL" />
      </geometry>
    </collision>
  </link>
  <joint
    name="Right_wheel_hinge"
    type="continuous">
    <origin
      xyz="-2.1041 -0.82602 -0.093708"
      rpy="3.1416 -0.74525 -1.5708" />
    <parent
      link="base_link" />
    <child
      link="Right_wheel" />
    <axis
      xyz="0 -1 0" />
    <dynamics
      friction="0.02" />
  </joint>
  <link
    name="Left_wheel">
    <inertial>
      <origin
        xyz="-1.0446E-05 0.1189 -1.31E-05"
        rpy="0 0 0" />
      <mass
        value="17.568" />
      <inertia
        ixx="0.0011571"
        ixy="-5.0608E-06"
        ixz="-3.9775E-08"
        iyy="8.1597E-08"
        iyz="-6.3467E-06"
        izz="0.0011571" />
    </inertial>
    <visual>
      <origin
        xyz="0 0 0"
        rpy="0 0 0" />
      <geometry>
        <mesh
          filename="package://soybot_1/meshes/Left_wheel.STL" />
      </geometry>
      <material
        name="">
        <color
          rgba="0.79216 0.81961 0.93333 1" />
      </material>
    </visual>
    <collision>
      <origin
        xyz="0 0 0"
        rpy="0 0 0" />
      <geometry>
        <mesh
          filename="package://soybot_1/meshes/Left_wheel.STL" />
      </geometry>
    </collision>
  </link>
  <joint
    name="Left_wheel_hinge"
    type="continuous">
    <origin
      xyz="0 -0.82602 -0.093708"
      rpy="0 0.072102 1.5708" />
    <parent
      link="base_link" />
    <child
      link="Left_wheel" />
    <axis
      xyz="0 -1 0" />
    <dynamics
      friction="0.02" />
  </joint>
</robot>