<sdf version='1.6'>
  <model name='soybot_1'>
    <link name='base_link'>
      <pose frame=''>0 0 0 0 -0 0</pose>
      <inertial>
        <pose frame=''>-1.15 0.55274 -0.039417 0 -0 0</pose>
        <mass>357.06</mass>
        <inertia>
          <ixx>197.79</ixx>
          <ixy>-3.3723e-14</ixy>
          <ixz>0.00044033</ixz>
          <iyy>340.98</iyy>
          <iyz>-8.6326</iyz>
          <izz>489.98</izz>
        </inertia>
      </inertial>
      <collision name='base_link_collision'>
        <pose frame=''>0 0 0 0 -0 0</pose>
        <geometry>
          <mesh>
            <scale>1 1 1</scale>
            <uri>model://soybot_1/meshes/base_link.STL</uri>
          </mesh>
        </geometry>
      </collision>
      <visual name='base_link_visual'>
        <pose frame=''>0 0 0 0 -0 0</pose>
        <geometry>
          <mesh>
            <scale>1 1 1</scale>
            <uri>model://soybot_1/meshes/base_link.STL</uri>
          </mesh>
        </geometry>
      </visual>
    </link>
    <link name='Left_wheel'>
      <pose frame=''>0 -0.82602 -0.093708 0 0.072102 1.5708</pose>
      <inertial>
        <pose frame=''>-1e-05 0.1189 -1.3e-05 0 -0 0</pose>
        <mass>17.568</mass>
        <inertia>
          <ixx>0.0011571</ixx>
          <ixy>-5.0608e-06</ixy>
          <ixz>-3.9775e-08</ixz>
          <iyy>8.1597e-08</iyy>
          <iyz>-6.3467e-06</iyz>
          <izz>0.0011571</izz>
        </inertia>
      </inertial>
      <collision name='Left_wheel_collision'>
        <pose frame=''>0 0 0 0 -0 0</pose>
        <geometry>
          <mesh>
            <scale>1 1 1</scale>
            <uri>model://soybot_1/meshes/Left_wheel.STL</uri>
          </mesh>
        </geometry>
      </collision>
      <visual name='Left_wheel_visual'>
        <pose frame=''>0 0 0 0 -0 0</pose>
        <geometry>
          <mesh>
            <scale>1 1 1</scale>
            <uri>model://soybot_1/meshes/Left_wheel.STL</uri>
          </mesh>
        </geometry>
      </visual>
    </link>
    <joint name='Left_wheel_hinge' type='revolute'>
      <child>Left_wheel</child>
      <parent>base_link</parent>
      <axis>
        <xyz>1 4e-06 0</xyz>
        <limit>
          <lower>-1e+16</lower>
          <upper>1e+16</upper>
        </limit>
        <dynamics>
          <damping>0</damping>
          <friction>0.02</friction>
          <spring_reference>0</spring_reference>
          <spring_stiffness>0</spring_stiffness>
        </dynamics>
        <use_parent_model_frame>1</use_parent_model_frame>
      </axis>
    </joint>
    <link name='Right_wheel'>
      <pose frame=''>-2.1041 -0.82602 -0.093708 -3.14159 -0.74525 -1.5708</pose>
      <inertial>
        <pose frame=''>0 0.077003 1.7e-05 0 -0 0</pose>
        <mass>17.568</mass>
        <inertia>
          <ixx>0.0011571</ixx>
          <ixy>-3.6541e-13</ixy>
          <ixz>8.5652e-17</ixz>
          <iyy>8.1597e-08</iyy>
          <iyz>-8.1174e-06</iyz>
          <izz>0.0011571</izz>
        </inertia>
      </inertial>
      <collision name='Right_wheel_collision'>
        <pose frame=''>0 0 0 0 -0 0</pose>
        <geometry>
          <mesh>
            <scale>1 1 1</scale>
            <uri>model://soybot_1/meshes/Right_wheel.STL</uri>
          </mesh>
        </geometry>
      </collision>
      <visual name='Right_wheel_visual'>
        <pose frame=''>0 0 0 0 -0 0</pose>
        <geometry>
          <mesh>
            <scale>1 1 1</scale>
            <uri>model://soybot_1/meshes/Right_wheel.STL</uri>
          </mesh>
        </geometry>
      </visual>
    </link>
    <joint name='Right_wheel_hinge' type='revolute'>
      <child>Right_wheel</child>
      <parent>base_link</parent>
      <axis>
        <xyz>1 1e-06 5e-06</xyz>
        <limit>
          <lower>-1e+16</lower>
          <upper>1e+16</upper>
        </limit>
        <dynamics>
          <damping>0</damping>
          <friction>0.02</friction>
          <spring_reference>0</spring_reference>
          <spring_stiffness>0</spring_stiffness>
        </dynamics>
        <use_parent_model_frame>1</use_parent_model_frame>
      </axis>
    </joint>
  </model>
</sdf>
