<?xml version="1.0"?>
<robot  name="soybot_1">


<!-- LINKS -->

<link name="base_link">
<visual>
  <origin xyz="0 0 0" rpy="0 0 0" />
  <geometry>
    <mesh
      filename="package://soybot_1/meshes/base_link.STL" />
  </geometry>
  <material
    name="">
    <color
      rgba="0.75294 0.75294 0.75294 1" />
  </material>
</visual>
<collision>
  <origin
    xyz="0 1.15 0.315"
    rpy="0 0 1.5707" />
  <geometry>
    <mesh
      filename="package://soybot_1/meshes/base_link_2.STL" />
  </geometry>
</collision>

<collision>
  <origin
    xyz="-0.525 1.05 0.115" rpy="0 0 1.5707" />
  <geometry>
  	<sphere radius="0.13"/>
  </geometry>
</collision>

<collision>
  <origin
    xyz="-0.525 -1.05 0.115" rpy="0 0 1.5707" />
  <geometry>
  	<sphere radius="0.13"/>
  </geometry>
</collision>

<inertial>
  <origin xyz="0 0 0.5" rpy="0 0 0" />
  <mass
    value="5.753" />
		<inertia 
		ixx = "0.667" ixy = "-00.010" ixz = "0.003" 
		iyy = "0.486" iyz = "0.00" 
		izz = "1.126"/>
</inertial>

</link>
  
<link name="right_wheel">
	<visual>
		<origin rpy="0 0 0" xyz="0 0 0"/>
		<geometry>
			<mesh filename = 
			"package://soybot_1/meshes/Right_wheel.STL" />
		</geometry>
	</visual>
	<collision>
		<origin rpy="0 0 0" xyz="0 -0.08 0"/>
		<geometry>
			<mesh filename = 
			"package://sb2_urdf/models/collision_wheel_8.dae" />
		</geometry>
	</collision>
	<inertial>
		<origin rpy="0 0 0" xyz="0.0 -0.08 0.00"/>
		<mass value="17.568"/>
		<inertia
		ixx = "0.28" ixy = "-0.00" ixz = "0.00"
		iyy = "0.49" iyz = "-0.00" 
		izz = "0.28"/>
	</inertial>
</link>

<link name="left_wheel">
	<visual>
		<origin rpy="0 0 3.1415" xyz="0 0 0"/>
		<geometry>
			<mesh filename = 
			"package://soybot_1/meshes/Right_wheel.STL" />
		</geometry>
	</visual>
	<collision>
		<origin rpy="0 0 3.1415" xyz="0 0.08 0"/>
		<geometry>
			<mesh filename = 
			"package://sb2_urdf/models/collision_wheel_8.dae" />
		</geometry>
	</collision>
	<inertial>
		<origin rpy="0 0 0" xyz="0.00 0.08 0.00"/>
		<mass value="17.568"/>
		<inertia
		ixx = "0.28" ixy = "-0.00" ixz = "0.00"
		iyy = "0.49" iyz = "-0.00" 
		izz = "0.28"/>
	</inertial>
</link>

<!-- JOINTS -->
<!--Wheels and base -->
<joint name="Right_wheel_hinge" type="continuous">
	<origin xyz="0.825 -0.955 0.225" rpy="0 0 0" />
	<parent link="base_link"/>
	<child link="right_wheel" />
	<axis xyz="0 1 0" />
	<dynamics damping="0.13" friction="0.02" />
</joint>

<joint name="Left_wheel_hinge" type="continuous">
	<origin xyz="0.825 0.955 0.225" rpy="0 0 0" />
	<parent link="base_link"/>
	<child link="left_wheel" />
	<axis xyz="0 1 0" />
	<dynamics damping="0.13" friction="0.02" />
</joint>

<!-- Plugins -->
<!-- Differential Driver Plugin -->
<gazebo>	
  <plugin name="differential_drive_controller" filename="libgazebo_ros_diff_drive.so">
    <alwaysOn>true</alwaysOn>
    <legacyMode>false</legacyMode>
    <updateRate>50</updateRate>
    <leftJoint>Left_wheel_hinge</leftJoint>
    <rightJoint>Right_wheel_hinge</rightJoint>
    <wheelSeparation>2.1</wheelSeparation>
    <wheelDiameter>0.4</wheelDiameter>
    <torque>500</torque>
    <commandTopic>/soybot/cmd_vel</commandTopic>
    <odometryTopic>/odom</odometryTopic>
    <odometryFrame>/odom</odometryFrame>
    <robotBaseFrame>base_link</robotBaseFrame>
    <wheelTorque>2000</wheelTorque>
  </plugin>  
</gazebo>


   
  
</robot>
